<?xml version="1.0"?>  
<robot name="mybot" xmlns:xacro="http://ros.org/wiki/xacro">  

  <xacro:include filename="$(find tm_gazebo)/launch/camen.gazebo.xacro" /> 

  <link name="base_footprint"/>

  <joint name="base_joint" type="fixed">  
    <parent link="base_footprint"/>  
    <child link="base_link"/>  
    <origin rpy="0 0 0" xyz="0 0 0"/>  
  </joint>  
  
  <link name="base_link">  
    <inertial>
     <origin xyz="0 0 0" rpy="0 0 0"/>
     <mass value="0.1"/>
     <inertia ixx="0.0001"  ixy="0"  ixz="0" iyy="0.0001" iyz="0" izz="0.001" />
    </inertial>

    <visual>  
      <geometry>  
        <box size="0.25 0.16 0.05"/>  
      </geometry>  
      <origin rpy="0 0 0" xyz="0 0 0"/>  
      <material name="blue">  
          <color rgba="0 0 0.8 1"/>  
      </material>  
    </visual>  

   <collision>
     <origin xyz="0 0 0" rpy="0 0 0"/>
     <geometry>
       <box size="0.25 0.16 0.05"/>
     </geometry>
   </collision>

  </link>  
 
  <link name="right_wheel_link">  
    <inertial>
     <origin xyz="0 0 0" rpy="0 0 0"/>
     <mass value="0.1"/>
     <inertia ixx="0.0001"  ixy="0"  ixz="0" iyy="0.0001" iyz="0" izz="0.0001" />
    </inertial>

    <visual>  
      <geometry>  
        <cylinder length="0.02" radius="0.025"/>  
      </geometry>  
      <material name="black">  
        <color rgba="0 0 0 1"/>  
      </material>  
    </visual>  

    <collision>
     <origin xyz="0 0 0" rpy="0 0 0"/>
     <geometry>
       <cylinder length="0.02" radius="0.025"/> 
     </geometry>
    </collision>
  </link>  
 
  <joint name="right_wheel_joint" type="continuous">  
    <axis xyz="0 0 -1"/>  
    <parent link="base_link"/>  
    <child link="right_wheel_link"/>  
    <origin rpy="1.5707 0 0" xyz=" 0.1 -0.09 -0.03"/>  
  </joint>  
 
  <link name="left_wheel_link">  
    <inertial>
     <origin xyz="0 0 0" rpy="0 0 0"/>
     <mass value="0.1"/>
     <inertia ixx="0.0001"  ixy="0"  ixz="0" iyy="0.0001" iyz="0" izz="0.0001" />
    </inertial>

    <visual>  
      <geometry>  
        <cylinder length="0.02" radius="0.025"/>  
      </geometry>  
      <material name="black">  
        <color rgba="0 0 0 1"/>  
      </material>  
    </visual>  

    <collision>
     <origin xyz="0 0 0" rpy="0 0 0"/>
     <geometry>
       <cylinder length="0.02" radius="0.025"/> 
     </geometry>
    </collision>   
  </link>  
 
  <joint name="left_wheel_joint" type="continuous">  
    <axis xyz="0 0 -1"/>  
    <parent link="base_link"/>  
    <child link="left_wheel_link"/>  
    <origin rpy="1.5707 0 0" xyz="0.1 0.09 -0.03"/>  
  </joint>  
 
  <link name="ball_wheel_link">  
    <inertial>
     <origin xyz="0 0 0" rpy="0 0 0"/>
     <mass value="0.1"/>
     <inertia ixx="0"  ixy="0"  ixz="0" iyy="0" iyz="0" izz="0" />
    </inertial>

    <visual>  
      <geometry>  
        <sphere radius="0.025"/>  
      </geometry>  
      <material name="black">  
        <color rgba="0 0 0 1"/>  
      </material>  
    </visual>  

    <collision>
     <origin xyz="0 0 0" rpy="0 0 0"/>
     <geometry>
       <sphere radius="0.025"/> 
     </geometry>
    </collision>   
  </link>  

  <joint name="ball_wheel_joint" type="fixed">  
    <axis xyz="0 0 1"/>  
    <parent link="base_link"/>  
    <child link="ball_wheel_link"/>  
    <origin rpy="0 0 0" xyz="-0.10 0 -0.03"/>  
  </joint>  
  <!-- imu sensor -->
  <link name="imu">  
    <visual>  
      <geometry>  
        <box size="0.01 0.01 0.01"/>  
      </geometry>  
      <material name="white">  
          <color rgba="1 1 1 1"/>  
      </material>  
    </visual>  
  </link>  

  <joint name="imu_joint" type="fixed">  
    <parent link="base_link"/>  
    <child link="imu"/>  
    <origin xyz="0.08 0 0.025"/>  
  </joint> 

  <!-- camera -->
  <link name="base_camera_link">  
    <visual>  
      <geometry>  
        <box size="0.02 0.03 0.03"/>  
      </geometry>  
      <material name="white">  
          <color rgba="1 1 1 1"/>  
      </material>  
    </visual>  
  </link>  

  <joint name="camera_joint" type="fixed">  
    <parent link="base_link"/>  
    <child link="base_camera_link"/>  
    <origin xyz="0.1 0 0.025"/>  
  </joint> 
  <!-- laser lidar -->
  <link name="base_laser_link">  
    <visual>  
      <geometry>  
        <cylinder length="0.06" radius="0.04"/>   
      </geometry>  
      <material name="white">  
          <color rgba="1 1 1 1"/>  
      </material>  
    </visual>  
  </link>  
  
  <joint name="laser_joint" type="fixed">  
    <parent link="base_link"/>  
    <child link="base_laser_link"/>  
    <origin xyz="0 0.0 0.06"/>  
  </joint> 


</robot>